import { Callout } from "nextra-theme-docs";

# Error handling

## Exceptions

Dart 코드는 예외를 던지고 잡을 수 있다.  
예외는 예상치 못한 일이 발생했음을 나타내는 오류이다.  
예외가 포착되지 않으면 예외를 발생시킨 격리가 일시 중단되고 일반적으로 격리와 해당 프로그램이 종료된다.

Java와 달리 Dart의 모든 예외는 확인되지 않은 예외이다.  
메서드는 어떤 예외를 던질 수 있는지 선언하지 않으며 예외를 잡을 필요가 없다.

Dart는 [Exception](https://api.dart.dev/stable/3.0.6/dart-core/Exception-class.html) 및 [Error](https://api.dart.dev/stable/3.0.6/dart-core/Error-class.html) 유형뿐만 아니라 수많은 사전 정의된 하위 유형을 제공한다.  
물론 자신만의 예외를 정의할 수 있다.  
그러나 Dart 프로그램은 Exception 및 Error 객체뿐 아니라 null이 아닌 모든 객체를 예외로 던질 수 있다.

<br />

### Throw

다음은 예외를 던지거나 발생시키는 예이다.

```dart
throw FormatException('Expected at least 1 section');

```

임의의 개체를 던질 수도 있다.

```dart
throw 'Out of llamas!';
```

<Callout type="info">
  Production-quality 코드는 일반적으로 오류 또는 예외를 구현하는 유형을
  발생시킨다.
</Callout>

예외를 던지는 것은 표현식이기 때문에 `=> 문`뿐만 아니라 표현식을 허용하는 다른 모든 곳에서 예외를 던질 수 있다.

```dart
void distanceTo(Point other) => throw UnimplementedError();
```

<br />

### catch

예외를 포착하거나 캡처하면 예외가 전파되지 않는다(예외를 다시 발생시키지 않는 한).  
예외를 포착하면 처리할 기회가 생긴다.

```dart
try {
  breedMoreLlamas();
} on OutOfLlamasException {
  buyMoreLlamas();
}
```

둘 이상의 예외 유형을 throw할 수 있는 코드를 처리하려면 여러 catch 절을 지정할 수 있다.  
던져진 객체의 유형과 일치하는 첫 번째 catch 절이 예외를 처리한다.  
catch 절이 유형을 지정하지 않으면 해당 절은 모든 유형의 throw된 객체를 처리할 수 있다.

```dart
try {
  breedMoreLlamas();
} on OutOfLlamasException {
  // 특정 예외
  buyMoreLlamas();
} on Exception catch (e) {
  // 기타 예외 사항
  print('Unknown exception: $e');
} catch (e) {
  // 지정된 유형 없음, 모두 처리
  print('Something really unknown: $e');
}
```

앞의 코드에서 볼 수 있듯이 `on` 또는 `catch`를 사용하거나 둘 다를 사용할 수 있다.  
예외 유형을 지정해야 하는 경우 `on`을 사용한다.  
예외 처리기에 예외 개체가 필요한 경우 `catch`를 사용한다.

`catch()`에 하나 또는 두 개의 매개변수를 지정할 수 있다.  
첫 번째는 throw된 예외이고 두 번째는 스택 추적([StackTrace](https://api.dart.dev/stable/3.0.6/dart-core/StackTrace-class.html) 개체)이다.

```dart
try {
  // ···
} on Exception catch (e) {
  print('Exception details:\n $e');
} catch (e, s) {
  print('Exception details:\n $e');
  print('Stack trace:\n $s');
}
```

propagate를 허용하면서 예외를 부분적으로 처리하려면 `rethrow` 키워드를 사용하자.

```dart {7}
void misbehave() {
  try {
    dynamic foo = true;
    print(foo++); // Runtime error
  } catch (e) {
    print('misbehave() partially handled ${e.runtimeType}.');
    rethrow; // 호출자가 예외를 볼 수 있도록 허용한다.
  }
}

void main() {
  try {
    misbehave();
  } catch (e) {
    print('main() finished handling ${e.runtimeType}.');
  }
}
```

<br />

### Finally

예외 발생 여부에 관계없이 일부 코드가 실행되도록 하려면 finally 절을 사용하자.  
예외와 일치하는 catch 절이 없으면 finally 절이 실행된 후 예외가 전파된다.

```dart
try {
  breedMoreLlamas();
} finally {
  // 예외가 발생하더라도 항상 cleanLlamaStalls()를 실행한다.
  cleanLlamaStalls();
}
```

<br />

## Assert

개발 중에는 assert 문을 사용한다.  
`assert(<condition>, <optionalMessage>);`  
부울 조건이 거짓인 경우 정상적인 실행을 방해한다.

```dart
// 변수에 null이 아닌 값이 있는지 확인하자.
assert(text != null);

// 값이 100 미만인지 확인하자.
assert(number < 100);

// 이것이 https URL인지 확인하자.
assert(urlString.startsWith('https'));
```

assertion에 메시지를 첨부하려면 `assert`의 두 번째 인수로 문자열을 추가한다.

```dart
assert(urlString.startsWith('https'),
    'URL ($urlString) should start with "https".');
```

`assert`에 대한 첫 번째 인수는 부울 값으로 확인되는 모든 식일 수 있다.  
식의 값이 true이면 assertion이 성공하고 실행이 계속된다.  
false이면 assertion이 실패하고 예외([AssertionError](https://api.dart.dev/stable/3.0.6/dart-core/AssertionError-class.html))가 발생한다.

프로덕션 코드에서는 assertion이 무시되고 assertion에 대한 인수가 평가되지 않는다.
